Workbook
Name MetroNames: Metros!$B$4:$B$385
Name MetroTable: Metros!$A$4:$I$385
Name Income: Model!$B$4
Name Rate: Model!$B$5
Name DownShare: Model!$B$6
Name TaxRate: Model!$B$7
Name InsuranceRate: Model!$B$8
Name TermYears: Model!$B$9
Name AffordableLine: Model!$B$10
Name MetroPick: Model!$B$3
Name MedianHome: Model!$E$3
Name Payment: Model!$E$9
Name PaymentShare: Model!$E$10
Name AffordablePrice: Model!$E$11

Sheet Model
A1: The affordability model: pick a metro, type an income, a rate, a down payment share, a tax rate and an insurance rate. Yellow cells are inputs; everything else is a formula.
A3: Metro | B3: New York-Newark-Jersey City, NY-NJ | D3: Median home (latest quarter) | E3: =INDEX(Metros!$D$4:$D$5000,MATCH(MetroPick,MetroNames,0))
A4: Annual household income | B4: 85000 | D4: Metro median income | E4: =INDEX(Metros!$E$4:$E$5000,MATCH(MetroPick,MetroNames,0))
A5: Mortgage rate (percent) | B5: 7.32 | D5: Metro median rent (monthly) | E5: =INDEX(Metros!$F$4:$F$5000,MATCH(MetroPick,MetroNames,0))
A6: Down payment share | B6: 0.1 | D6: Latest quarter | E6: =INDEX(Metros!$G$4:$G$5000,MATCH(MetroPick,MetroNames,0))
A7: Property tax rate (share of value per year) | B7: 0.011
A8: Insurance rate (share of value per year) | B8: 0.004 | D8: Loan amount | E8: =E3*(1-DownShare)
A9: Loan term (years) | B9: 30 | D9: Monthly payment (principal and interest) | E9: =-PMT(Rate/100/12,TermYears*12,E8)
A10: Affordable line (share of income) | B10: 0.3 | D10: Payment share of income | E10: =12*E9/Income
D11: Affordable price at the line | E11: =-PV(Rate/100/12,TermYears*12,AffordableLine*Income/12)/(1-DownShare)
D12: Monthly cost with taxes and insurance | E12: =E9+E3*(TaxRate+InsuranceRate)/12
D13: Full cost share of income | E13: =12*E12/Income
D14: Income needed for the median home at the line | E14: =12*E9/AffordableLine
D15: Rent share of income at the metro median rent | E15: =12*E5/Income
D16: Can the income carry the median home at the line | E16: =IF(E11>=E3,"yes","no")
A19: Amortisation
A20: Month | B20: Payment | C20: Interest | D20: Principal | E20: Balance | G20: Total interest over the term | H20: =SUM(C21:C380)
A21: 1 | B21: =Payment | C21: =E8*Rate/100/12 | D21: =B21-C21 | E21: =E8-D21 | G21: Total paid | H21: =SUM(B21:B380)
A22: =A21+1 | B22: =IF(A22<=TermYears*12,Payment,0) | C22: =E21*Rate/100/12 | D22: =B22-C22 | E22: =MAX(E21-D22,0)
A23: =A22+1 | B23: =IF(A23<=TermYears*12,Payment,0) | C23: =E22*Rate/100/12 | D23: =B23-C23 | E23: =MAX(E22-D23,0) | G23: Public data from the Federal Housing Finance Agency, the Census Bureau (American Community Survey, Building Permits Survey, Population Estimates), the Department of Housing and Urban Development and the Consumer Financial Protection Bureau (HMDA), with mortgage rates from Freddie Mac under its terms of use. Metros are real and appear as they do in the public record; no household, borrower or address appears. The findings are a portfolio analysis, not financial advice, not a market forecast and not a fair lending finding.
A24: =A23+1 | B24: =IF(A24<=TermYears*12,Payment,0) | C24: =E23*Rate/100/12 | D24: =B24-C24 | E24: =MAX(E23-D24,0) | G24: Mortgage rates: Freddie Mac Primary Mortgage Market Survey, used under its terms of use.
A25: =A24+1 | B25: =IF(A25<=TermYears*12,Payment,0) | C25: =E24*Rate/100/12 | D25: =B25-C25 | E25: =MAX(E24-D25,0)
A26: =A25+1 | B26: =IF(A26<=TermYears*12,Payment,0) | C26: =E25*Rate/100/12 | D26: =B26-C26 | E26: =MAX(E25-D26,0)
A27: =A26+1 | B27: =IF(A27<=TermYears*12,Payment,0) | C27: =E26*Rate/100/12 | D27: =B27-C27 | E27: =MAX(E26-D27,0)
A28: =A27+1 | B28: =IF(A28<=TermYears*12,Payment,0) | C28: =E27*Rate/100/12 | D28: =B28-C28 | E28: =MAX(E27-D28,0)
A29: =A28+1 | B29: =IF(A29<=TermYears*12,Payment,0) | C29: =E28*Rate/100/12 | D29: =B29-C29 | E29: =MAX(E28-D29,0)
A30: =A29+1 | B30: =IF(A30<=TermYears*12,Payment,0) | C30: =E29*Rate/100/12 | D30: =B30-C30 | E30: =MAX(E29-D30,0)
A31: =A30+1 | B31: =IF(A31<=TermYears*12,Payment,0) | C31: =E30*Rate/100/12 | D31: =B31-C31 | E31: =MAX(E30-D31,0)
A32: =A31+1 | B32: =IF(A32<=TermYears*12,Payment,0) | C32: =E31*Rate/100/12 | D32: =B32-C32 | E32: =MAX(E31-D32,0)
A33: =A32+1 | B33: =IF(A33<=TermYears*12,Payment,0) | C33: =E32*Rate/100/12 | D33: =B33-C33 | E33: =MAX(E32-D33,0)
A34: =A33+1 | B34: =IF(A34<=TermYears*12,Payment,0) | C34: =E33*Rate/100/12 | D34: =B34-C34 | E34: =MAX(E33-D34,0)
A35: =A34+1 | B35: =IF(A35<=TermYears*12,Payment,0) | C35: =E34*Rate/100/12 | D35: =B35-C35 | E35: =MAX(E34-D35,0)
A36: =A35+1 | B36: =IF(A36<=TermYears*12,Payment,0) | C36: =E35*Rate/100/12 | D36: =B36-C36 | E36: =MAX(E35-D36,0)
... A380: =A379+1 | B380: =IF(A380<=TermYears*12,Payment,0) | C380: =E379*Rate/100/12 | D380: =B380-C380 | E380: =MAX(E379-D380,0)

Sheet Read me
A1: doorstep: can anyone still afford a home. Every number on the chapter sheets is rendered from results/manifest.json, the same file the site and the memo read.
A3: Model sheet: pick a metro in B3 (a validated list from the Metros sheet), type an income in B4, a rate in B5 (percent), a down payment share in B6, and tax and insurance rates in B7 and B8.
A4: The payment is PMT on the loan at the monthly rate over the term; the payment share is twelve payments over the income; the affordable price is PV of the line share of income over the term, grossed up for the down payment.
A5: The amortisation table recalculates for every input. The headline figures of the story use principal and interest only, with taxes and insurance as workbook inputs, as the definitions document says.
A7: Metros sheet: the latest anchored median home (FHFA all transactions index anchored to the census median value in the anchor year), the census median household income and median gross rent of the latest one year release, and the latest quarterly PMMS rate.
A9: Public data from the Federal Housing Finance Agency, the Census Bureau (American Community Survey, Building Permits Survey, Population Estimates), the Department of Housing and Urban Development and the Consumer Financial Protection Bureau (HMDA), with mortgage rates from Freddie Mac under its terms of use. Metros are real and appear as they do in the public record; no household, borrower or address appears. The findings are a portfolio analysis, not financial advice, not a market forecast and not a fair lending finding.
A10: Mortgage rates: Freddie Mac Primary Mortgage Market Survey, used under its terms of use.
A11: Manifest as of 2026-10-23.

Sheet Metros
A1: Every metropolitan area the calculator covers: the latest anchored median home, the census median income and rent, and the latest quarterly rate
A3: Code | B3: Metro | C3: Households | D3: Median home | E3: Median income | F3: Median rent (monthly) | G3: Latest quarter | H3: Latest rate | I3: Income year
A4: 10180 | B4: Abilene, TX | C4: 66099 | D4: 225739.51 | E4: 63390 | F4: 1173 | G4: 2026Q2 | H4: 6.4146154 | I4: 2024
A5: 10420 | B5: Akron, OH | C5: 303143 | D5: 266117.32 | E5: 71364 | F5: 1059 | G5: 2026Q2 | H5: 6.4146154 | I5: 2024
A6: 10500 | B6: Albany, GA | C6: 56259 | D6: 209077.76 | E6: 56851 | F6: 975 | G6: 2026Q2 | H6: 6.4146154 | I6: 2024
A7: 10540 | B7: Albany, OR | C7: 50968 | D7: 407881.72 | E7: 80422 | F7: 1363 | G7: 2026Q2 | H7: 6.4146154 | I7: 2024
A8: 10580 | B8: Albany-Schenectady-Troy, NY | C8: 398349 | D8: 387659.37 | E8: 86637 | F8: 1341 | G8: 2026Q2 | H8: 6.4146154 | I8: 2024
A9: 10740 | B9: Albuquerque, NM | C9: 378607 | D9: 353121.87 | E9: 76097 | F9: 1220 | G9: 2026Q2 | H9: 6.4146154 | I9: 2024
A10: 10780 | B10: Alexandria, LA | C10: 58271 | D10: 191619.81 | E10: 55909 | F10: 899 | G10: 2026Q2 | H10: 6.4146154 | I10: 2024
A11: 10900 | B11: Allentown-Bethlehem-Easton, PA-NJ | C11: 341143 | D11: 408033.07 | E11: 83974 | F11: 1458 | G11: 2026Q2 | H11: 6.4146154 | I11: 2024
A12: 11020 | B12: Altoona, PA | C12: 50837 | D12: 203449.88 | E12: 66994 | F12: 895 | G12: 2026Q2 | H12: 6.4146154 | I12: 2024
A13: 11100 | B13: Amarillo, TX | C13: 105814 | D13: 238010.74 | E13: 69595 | F13: 1097 | G13: 2026Q2 | H13: 6.4146154 | I13: 2024
A14: 11180 | B14: Ames, IA | C14: 50869 | D14: 283872.16 | E14: 70873 | F14: 950 | G14: 2026Q2 | H14: 6.4146154 | I14: 2024
A15: 11260 | B15: Anchorage, AK | C15: 148919 | D15: 455549.28 | E15: 102698 | F15: 1491 | G15: 2026Q2 | H15: 6.4146154 | I15: 2024
... A385: 49740 | B385: Yuma, AZ | C385: 83795 | D385: 242176.86 | E385: 66844 | F385: 1099 | G385: 2026Q2 | H385: 6.4146154 | I385: 2024

Sheet Checks
A1: Three metros through the same formulas as the Model sheet, for the recalculation test
A3: Metro | B3: Income | C3: Rate | D3: Down share | E3: Median home | F3: Payment | G3: Payment share | H3: Affordable price
A4: New York-Newark-Jersey City, NY-NJ | B4: 100000 | C4: 7.32 | D4: 0.1 | E4: =INDEX(Metros!$D$4:$D$5000,MATCH(A4,MetroNames,0)) | F4: =-PMT(C4/100/12,TermYears*12,E4*(1-D4)) | G4: =12*F4/B4 | H4: =-PV(C4/100/12,TermYears*12,AffordableLine*B4/12)/(1-D4)
A5: Los Angeles-Long Beach-Anaheim, CA | B5: 96000 | C5: 7.32 | D5: 0.1 | E5: =INDEX(Metros!$D$4:$D$5000,MATCH(A5,MetroNames,0)) | F5: =-PMT(C5/100/12,TermYears*12,E5*(1-D5)) | G5: =12*F5/B5 | H5: =-PV(C5/100/12,TermYears*12,AffordableLine*B5/12)/(1-D5)
A6: Chicago-Naperville-Elgin, IL-IN | B6: 91000 | C6: 7.32 | D6: 0.1 | E6: =INDEX(Metros!$D$4:$D$5000,MATCH(A6,MetroNames,0)) | F6: =-PMT(C6/100/12,TermYears*12,E6*(1-D6)) | G6: =12*F6/B6 | H6: =-PV(C6/100/12,TermYears*12,AffordableLine*B6/12)/(1-D6)

Sheet Ch1 payment share by year
A1: ch1.series: Source: the FHFA index anchored to the census, with Freddie Mac rates, model: Monte Carlo over the survey margins, every metropolitan area with a census income and an anchored value, 2005 to 2024, as of 2026-10-23.
A3: Year | B3: Metros | C3: Rate | D3: Median home | E3: Price to income | F3: Payment share | G3: Low | H3: High
A4: 2005 | B4: 372 | C4: 5.8667308 | D4: 247443.78 | E4: 4.8303193 | F4: 0.30831451 | G4: 0.3075711 | H4: 0.30928201
A5: 2006 | B5: 375 | C5: 6.4132692 | D5: 267981.88 | E5: 4.9836145 | F5: 0.33713404 | G5: 0.33641591 | H5: 0.33809074
A6: 2007 | B6: 375 | C6: 6.3373077 | D6: 266347.25 | E6: 4.7487201 | F6: 0.31869576 | G6: 0.31800536 | H6: 0.31965731
A7: 2008 | B7: 375 | C7: 6.0307418 | D7: 243578.89 | E7: 4.2082936 | F7: 0.27339208 | G7: 0.27279272 | H7: 0.27419546
A8: 2009 | B8: 378 | C8: 5.0391896 | D8: 224963.64 | E8: 4.0559418 | F8: 0.23620054 | G8: 0.23566116 | H8: 0.23692976
A9: 2010 | B9: 380 | C9: 4.7003594 | D9: 215841.36 | E9: 3.9441505 | F9: 0.22093244 | G9: 0.2204406 | H9: 0.22159104
A10: 2011 | B10: 380 | C10: 4.4478846 | D10: 207324.31 | E10: 3.755253 | F10: 0.20424105 | G10: 0.20378194 | H10: 0.20487481
A11: 2012 | B11: 380 | C11: 3.6575 | D11: 206903.85 | E11: 3.6589016 | F11: 0.18093747 | G11: 0.18052517 | H11: 0.18147063
A12: 2013 | B12: 380 | C12: 3.9755769 | D12: 217306.42 | E12: 3.7558165 | F12: 0.1930824 | G12: 0.19267656 | H12: 0.19364411
A13: 2014 | B13: 380 | C13: 4.1728159 | D13: 230823.02 | E13: 3.8787475 | F13: 0.20418751 | G13: 0.20376864 | H13: 0.20476945
A14: 2015 | B14: 380 | C14: 3.8470925 | D14: 243721.82 | E14: 3.9518224 | F14: 0.200015 | G14: 0.19956835 | H14: 0.20064422
A15: 2016 | B15: 381 | C15: 3.6540385 | D15: 257341.69 | E15: 4.0094654 | F15: 0.19818878 | G15: 0.19777145 | H15: 0.19875852
... A22: 2024 | B22: 382 | C22: 6.7211538 | D22: 449459.11 | E22: 4.9934869 | F22: 0.34875328 | G22: 0.3479779 | H22: 0.34989734

Sheet Ch1 anchor sensitivity
A1: ch1.anchor_sensitivity: Source: the FHFA index anchored to the census, with Freddie Mac rates, model: the index anchored to the census level, every metropolitan area with a census income and an anchored value, 2005 to 2024, as of 2026-10-23.
A3: Anchor year | B3: Latest payment share | C3: 2006 payment share | D3: Difference | E3: Metros above 2006 | F3: Note
A4: 2015 | B4: 0.34977226 | C4: 0.33836263 | D4: 0.011139474 | E4: 283
A5: 2017 | B5: 0.34846362 | C5: 0.33710378 | D5: 0.011189694 | E5: 283
A6: 2019 | B6: 0.34875328 | C6: 0.33713404 | D6: 0.011425722 | E6: 283 | F6: chosen
A7: 2023 | B7: 0.3347511 | C7: 0.32256749 | D7: 0.012235497 | E7: 283

Sheet Ch1 line interior test
A1: ch1.line_interior: Source: the FHFA index anchored to the census, with Freddie Mac rates, every metropolitan area with a census income and an anchored value, 2005 to 2024, as of 2026-10-23.
A3: Line | B3: Metros above | C3: Share
A4: 0.25 | B4: 263 | C4: 0.68848168
A5: 0.28 | B5: 191 | C5: 0.5
A6: 0.3 | B6: 161 | C6: 0.42146597
A7: 0.35 | B7: 94 | C7: 0.2460733

Sheet Ch2 rate shock by quarter
A1: ch2.decomposition: Source: the HMDA loan level extract, model: the price and rate decomposition, every metropolitan area with quarterly prices from 2019Q1 and loans in the base and test years (388 metros, 86 states), as of 2026-10-23.
A3: Quarter | B3: Rate | C3: Payment | D3: Price part | E3: Rate part
A4: 2019Q1 | B4: 4.3738462 | C4: 1315.9402 | D4: 0 | E4: 0
A5: 2019Q2 | B5: 4.0107692 | C5: 1278.6619 | D5: 19.376626 | E5: -56.654964
A6: 2019Q3 | B6: 3.6584615 | C6: 1238.9926 | D6: 34.740684 | E6: -111.68837
A7: 2019Q4 | B7: 3.7 | C7: 1255.0686 | D7: 45.291507 | E7: -106.1632
A8: 2020Q1 | B8: 3.5215385 | C8: 1240.6387 | D8: 59.631397 | E8: -134.93296
A9: 2020Q2 | B9: 3.2392308 | C9: 1209.4358 | D9: 73.267411 | E9: -179.77186
A10: 2020Q3 | B10: 2.9523077 | C10: 1184.4051 | D10: 95.096179 | E10: -226.63136
A11: 2020Q4 | B11: 2.7607143 | C11: 1179.6568 | D11: 124.59817 | E11: -260.88164
A12: 2021Q1 | B12: 2.8758333 | C12: 1226.3962 | D12: 159.55619 | E12: -249.1002
A13: 2021Q2 | B13: 3.0038462 | C13: 1315.0879 | D13: 240.47658 | E13: -241.32892
A14: 2021Q3 | B14: 2.8721429 | C14: 1361.5611 | D14: 322.95426 | E14: -277.33338
A15: 2021Q4 | B15: 3.0792308 | C15: 1444.8171 | D15: 377.64026 | E15: -248.76338
... A33: 2026Q2 | B33: 6.4146154 | C33: 2703.7682 | D33: 838.64379 | E33: 549.18412

Sheet Ch2 lock in thresholds
A1: ch2.threshold_interior: Source: the HMDA loan level extract, model: the lock in difference in differences, every metropolitan area with quarterly prices from 2019Q1 and loans in the base and test years (388 metros, 86 states), as of 2026-10-23.
A3: Threshold | B3: Coefficient | C3: Low | D3: High | E3: Placebo | F3: Note
A4: 3 | B4: -0.094234698 | C4: -0.14647829 | D4: -0.041991108 | E4: 0.0012267266
A5: 3.5 | B5: -0.067206488 | C5: -0.096443744 | D5: -0.037969233 | E5: 0.00079963817
A6: 4 | B6: -0.055799444 | C6: -0.077270956 | D6: -0.034327931 | E6: 0.00069104826 | F6: chosen

Sheet Ch3 burden bands
A1: ch3.bands: Source: the American Community Survey one year release, model: the cost burden shares, every metropolitan area with renters in the census tables, 2005 to 2024 (392 metros in 2024), as of 2026-10-23.
A3: Year | B3: Under 30 percent | C3: 30 to 50 percent | D3: 50 percent and over
A4: 2005 | B4: 0.50520677 | C4: 0.24351542 | D4: 0.25127781
A5: 2006 | B5: 0.50226734 | C5: 0.24629838 | D5: 0.25143428
A6: 2007 | B6: 0.50685416 | C6: 0.24753681 | D6: 0.24560904
A7: 2008 | B7: 0.50218296 | C7: 0.24684119 | D7: 0.25097585
A8: 2009 | B8: 0.48459696 | C8: 0.25158143 | D8: 0.26382161
A9: 2010 | B9: 0.47017296 | C9: 0.25547314 | D9: 0.2743539
A10: 2011 | B10: 0.4658791 | C10: 0.25444759 | D10: 0.27967331
A11: 2012 | B11: 0.47988447 | C11: 0.24984903 | D11: 0.2702665
A12: 2013 | B12: 0.48470588 | C12: 0.25066947 | D12: 0.26462465
A13: 2014 | B13: 0.48234171 | C13: 0.25439918 | D13: 0.26325911
A14: 2015 | B14: 0.49414568 | C14: 0.25134771 | D14: 0.25450661
A15: 2016 | B15: 0.50269502 | C15: 0.24779555 | D15: 0.24950944
... A22: 2024 | B22: 0.4823063 | C22: 0.2569297 | D22: 0.26076399

Sheet Ch3 burden by income
A1: ch3.by_income_group: Source: the American Community Survey one year release, model: the cost burden shares, every metropolitan area with renters in the census tables, 2005 to 2024 (392 metros in 2024), as of 2026-10-23.
A3: Income group | B3: Renters | C3: Burdened | D3: Severely burdened
A4: under 10k | B4: 2100866 | C4: 0.9780938 | D4: 0.93474167
A5: 10k to 20k | B5: 3318512 | C5: 0.86648293 | D5: 0.70455493
A6: 20k to 35k | B6: 4575863 | C6: 0.88303846 | D6: 0.59767961
A7: 35k to 50k | B7: 4532267 | C7: 0.78041364 | D7: 0.30834459
A8: 50k to 75k | B8: 6509505 | C8: 0.5614963 | D8: 0.10311398
A9: 75k to 100k | B9: 4512280 | C9: 0.30603065 | D9: 0.031808975
A10: 100k plus | B10: 9407120 | C10: 0.097476592 | D10: 0.0090300751

Sheet Ch3 line interior test
A1: ch3.line_interior: Source: the American Community Survey one year release, every metropolitan area with renters in the census tables, 2005 to 2024 (392 metros in 2024), as of 2026-10-23.
A3: Stated line | B3: Severe share | C3: Interval against the line | D3: Note
A4: 0.15 | B4: 0.26498664 | C4: clears
A5: 0.2 | B5: 0.26498664 | C5: clears | D5: chosen
A6: 0.25 | B6: 0.26498664 | C6: clears

Sheet Ch4 supply specifications
A1: ch4.specifications: Source: permits beside the price index, model: supply on weighted cells with fixed effects, 385 metropolitan areas over 5 windows of 5 years (1925 cells, 85 states), as of 2026-10-23.
A3: Specification | B3: Annual growth per permit per 100 households | C3: Low | D3: High | E3: Over the window | F3: Clusters
A4: with the demand control | B4: -0.016026728 | C4: -0.028625529 | D4: -0.0034279278 | E4: -0.080133642 | F4: 85
A5: without the demand control | B5: -0.00089011593 | C5: -0.0091764776 | D5: 0.0073962458 | E5: -0.0044505796 | F5: 85

Sheet Ch4 window interior test
A1: ch4.window_interior: Source: permits beside the price index, model: supply on weighted cells with fixed effects, 385 metropolitan areas over 5 windows of 5 years (1925 cells, 85 states), as of 2026-10-23.
A3: Window years | B3: Controlled | C3: Low | D3: High | E3: Uncontrolled | F3: Note
A4: 3 | B4: 3.6812984e-05 | C4: -0.013051679 | D4: 0.013125305 | E4: 0.011289205 | F4: degenerate
A5: 5 | B5: -0.016026728 | C5: -0.028625529 | D5: -0.0034279278 | E5: -0.00089011593 | F5: chosen
A6: 7 | B6: 0.0016046607 | C6: -0.012661355 | D6: 0.015870676 | E6: 0.010000462

Sheet Ch5 fair ranking
A1: ch5.largest: Source: the FHFA index anchored to the census, with Freddie Mac rates, model: Monte Carlo over the survey margins, every metropolitan area present in both the index and the census release of 2024 (382 metros); micropolitan areas excluded, as of 2026-10-23.
A3: Metro | B3: Households | C3: Median home | D3: Median income | E3: Payment share | F3: Low | G3: High | H3: Raw rank | I3: Adjusted rank | J3: Interval | K3: Moves
A4: Los Angeles-Long Beach-Anaheim, CA | B4: 4583939 | C4: 984120.99 | D4: 96405 | E4: 0.71295698 | F4: 0.7035244 | G4: 0.72215088 | H4: 7 | I4: 2 | J4: 1 to 4 | K4: yes
A5: San Diego-Chula Vista-Carlsbad, CA | B5: 1185092 | C5: 985574.54 | D5: 109132 | E5: 0.630742 | F5: 0.61743577 | G5: 0.64507657 | H5: 6 | I5: 8 | J5: 6 to 10 | K5: no
A6: San Francisco-Oakland-Fremont, CA | B6: 1770425 | C6: 1161939.1 | D6: 135590 | E6: 0.59850819 | F6: 0.58555715 | G6: 0.61168468 | H6: 2 | I6: 10 | J6: 10 to 12 | K6: yes
A7: New York-Newark-Jersey City, NY-NJ | B7: 7486828 | C7: 709339.05 | D7: 99852 | E7: 0.49614828 | F7: 0.49094206 | G7: 0.5015095 | H7: 18 | I7: 21 | J7: 18 to 24 | K7: no
A8: Miami-Fort Lauderdale-West Palm Beach, FL | B8: 2382154 | C8: 570253.52 | D8: 80625 | E8: 0.49398372 | F8: 0.48618187 | G8: 0.50204559 | H8: 33 | I8: 22 | J8: 18 to 25 | K8: yes
A9: Seattle-Tacoma-Bellevue, WA | B9: 1658652 | C9: 747400.42 | D9: 112388 | E9: 0.46445943 | F9: 0.45157234 | G9: 0.47759829 | H9: 15 | I9: 27 | J9: 24 to 33 | K9: yes
A10: Riverside-San Bernardino-Ontario, CA | B10: 1484661 | C10: 601160.92 | D10: 91013 | E10: 0.46131938 | F10: 0.45399114 | G10: 0.46870004 | H10: 29 | I10: 28 | J10: 25 to 33 | K10: no
A11: Boston-Cambridge-Newton, MA-NH | B11: 1970240 | C11: 724836.19 | D11: 117825 | E11: 0.42965197 | F11: 0.41909498 | G11: 0.4406506 | H11: 16 | I11: 41 | J11: 35 to 47 | K11: yes
A12: Denver-Aurora-Centennial, CO | B12: 1265606 | C12: 625143.63 | D12: 108046 | E12: 0.40409689 | F12: 0.39431823 | G12: 0.41431619 | H12: 23 | I12: 52 | J12: 47 to 61 | K12: yes
A13: Phoenix-Mesa-Chandler, AZ | B13: 1967378 | C13: 482838.59 | D13: 90133 | E13: 0.37413862 | F13: 0.36726605 | G13: 0.38114567 | H13: 58 | I13: 70 | J13: 65 to 80 | K13: yes
A14: Tampa-St. Petersburg-Clearwater, FL | B14: 1377328 | C14: 400906.52 | D14: 78275 | E14: 0.35771275 | F14: 0.3470261 | G14: 0.36907464 | H14: 106 | I14: 90 | J14: 76 to 100 | K14: yes
A15: Washington-Arlington-Alexandria, DC-VA-MD-WV | B15: 2415530 | C15: 619214.49 | D15: 126244 | E15: 0.34256639 | F15: 0.33725314 | G15: 0.34798042 | H15: 25 | I15: 102 | J15: 96 to 113 | K15: yes
... A23: St. Louis, MO-IL | B23: 1178246 | C23: 271171.95 | D23: 81679 | E23: 0.23187223 | F23: 0.2258438 | G23: 0.23820635 | H23: 223 | I23: 307 | J23: 289 to 318 | K23: yes

Sheet Ch6 borrowers by year
A1: ch6.by_year: Source: the HMDA extract beside the census incomes, model: the block bootstrap, every purchase loan on a principal residence in the extract, 2018 to 2025 (2,722,577 loans from 4,341 lenders in 2025), as of 2026-10-23.
A3: Year | B3: Loans | C3: Lenders | D3: Income ratio | E3: Low | F3: High | G3: Under 35 | H3: Above twice the median | I3: Value to income | J3: Spread p50
A4: 2018 | B4: 3389103 | C4: 5148 | D4: 1.280519 | E4: 1.247798 | F4: 1.3151407 | G4: 0.38368146 | H4: 0.22726072 | I4: 3.375 | J4: 0.4375
A5: 2019 | B5: 3533474 | C5: 5029 | D5: 1.2329674 | E5: 1.2043877 | F5: 1.2668758 | G5: 0.38270637 | H5: 0.20886951 | I5: 3.375 | J5: 0.4375
A6: 2020 | B6: 3861776 | C6: 4164 | D6: 1.244308 | E6: 1.224641 | F6: 1.2800142 | G6: 0.40708187 | H6: 0.21411237 | I6: 3.625 | J6: 0.3125
A7: 2021 | B7: 4097757 | C7: 4075 | D7: 1.2370114 | E7: 1.2170764 | F7: 1.2606541 | G7: 0.39009927 | H7: 0.21202404 | I7: 3.875 | J7: 0.3125
A8: 2022 | B8: 3317262 | C8: 4160 | D8: 1.3222311 | E8: 1.2982621 | F8: 1.3518267 | G8: 0.38877966 | H8: 0.23808731 | I8: 3.625 | J8: 0.3125
A9: 2023 | B9: 2664039 | C9: 4605 | D9: 1.3769799 | E9: 1.3494734 | F9: 1.40231 | G9: 0.39771002 | H9: 0.25462428 | I9: 3.375 | J9: 0.1875
A10: 2024 | B10: 2695601 | C10: 4433 | D10: 1.3591027 | E10: 1.3348717 | F10: 1.3805544 | G10: 0.39704726 | H10: 0.2511273 | I10: 3.375 | J10: 0.1875
A11: 2025 | B11: 2722577 | C11: 4341 | D11: 1.3861811 | E11: 1.3675061 | F11: 1.4145762 | G11: 0.39438407 | H11: 0.26698492 | I11: 3.375 | J11: 0.1875

Sheet Ch6 borrowers by metro
A1: ch6.largest_metros: Source: the HMDA extract beside the census incomes, model: the block bootstrap, every purchase loan on a principal residence in the extract, 2018 to 2025 (2,722,577 loans from 4,341 lenders in 2025), as of 2026-10-23.
A3: Metro | B3: Ratio 2019 | C3: Ratio 2025 | D3: Low | E3: High | F3: Change | G3: Under 35 2025
A4: New York-Newark-Jersey City, NY-NJ | B4: 1.473064 | C4: 1.7776309 | D4: 1.7275568 | E4: 1.8777791 | F4: 0.30456692 | G4: 0.36395538
A5: Dallas-Fort Worth-Arlington, TX | B5: 1.3492009 | C5: 1.3749151 | D5: 1.2670786 | E5: 1.4827516 | F5: 0.025714221 | G5: 0.38345746
A6: Chicago-Naperville-Elgin, IL-IN | B6: 1.1608008 | C6: 1.2944806 | D6: 1.2393963 | E6: 1.3495648 | F6: 0.1336798 | G6: 0.40471448
A7: Houston-Pasadena-The Woodlands, TX | B7: 1.3368404 | C7: 1.4431875 | D7: 1.3817753 | E7: 1.566012 | F7: 0.10634711 | G7: 0.37912587
A8: Atlanta-Sandy Springs-Roswell, GA | B8: 1.149954 | C8: 1.2724162 | D8: 1.2182708 | E8: 1.3265616 | F8: 0.12246218 | G8: 0.35171058
A9: Phoenix-Mesa-Chandler, AZ | B9: 1.1414516 | C9: 1.3036291 | D9: 1.2481555 | E9: 1.3591027 | F9: 0.16217745 | G9: 0.37492584
A10: Washington-Arlington-Alexandria, DC-VA-MD-WV | B10: 1.064746 | C10: 1.247584 | D10: 1.2079782 | E10: 1.2871899 | F10: 0.18283802 | G10: 0.34494079
A11: Philadelphia-Camden-Wilmington, PA-NJ-DE-MD | B11: 1.1739766 | C11: 1.3483764 | D11: 1.2933407 | E11: 1.4034122 | F11: 0.17439982 | G11: 0.41086911
A12: Los Angeles-Long Beach-Anaheim, CA | B12: 1.767943 | C12: 2.2042425 | D12: 2.1005135 | E12: 2.3598361 | F12: 0.4362995 | G12: 0.30233749
A13: Minneapolis-St. Paul-Bloomington, MN-WI | B13: 1.0454252 | C13: 1.1488032 | D13: 1.1488032 | E13: 1.1998611 | F13: 0.10337798 | G13: 0.43675661
A14: Detroit-Warren-Dearborn, MI | B14: 1.1422 | C14: 1.2761279 | D14: 1.2106854 | E14: 1.3415704 | F14: 0.13392794 | G14: 0.44335637
A15: Miami-Fort Lauderdale-West Palm Beach, FL | B15: 1.4549143 | C15: 1.8294574 | D15: 1.7054264 | E15: 1.8930233 | F15: 0.37454308 | G15: 0.29197494
... A23: St. Louis, MO-IL | B23: 1.1668699 | C23: 1.1936973 | D23: 1.132482 | E23: 1.2549125 | F23: 0.02682735 | G23: 0.44061603

Sheet Ch7 migration regression
A1: ch7.regression: Source: population estimates beside the price index, model: the migration regression with its placebo, 385 metropolitan areas with migration over 2020 and 2021 and the index in both windows (85 states), as of 2026-10-23.
A3: Window | B3: Growth per person per 100 residents of shock | C3: Low | D3: High | E3: p | F3: Clusters
A4: 2019Q4 to 2021Q4 | B4: 0.014758936 | C4: 0.0040479049 | D4: 0.025469967 | E4: 0.0074997933 | F4: 85
A5: 2016Q4 to 2018Q4 (placebo) | B5: -0.0077719744 | C5: -0.013513196 | D5: -0.0020307533 | E5: 0.0085703733 | F5: 85
A6: 2019Q4 to 2021Q4 (level alone, no pre pandemic control) | B6: 0.024100372 | C6: 0.018685128 | D6: 0.029515616 | E6: 1.1880221e-13 | F6: 85

Sheet Ch7 synthetic controls
A1: ch7.synthetic_controls: Source: population estimates beside the price index, model: synthetic control with placebo inference, 385 metropolitan areas with migration over 2020 and 2021 and the index in both windows (85 states), as of 2026-10-23.
A3: Metro | B3: Mean post gap | C3: Peak gap | D3: Peak quarter | E3: Latest gap | F3: Reversal since peak | G3: Permutation p | H3: Donors searched | I3: Top weights
A4: Panama City-Panama City Beach, FL | B4: 0.0072297 | C4: 0.093573379 | D4: 2023Q2 | E4: -0.019806004 | F4: 0.11337938 | G4: 0.82901554 | H4: 192 | I4: Boise City 0.31; Michigan City-La Porte 0.25; Monroe 0.18
A5: Amherst Town-Northampton, MA | B5: -0.01217181 | C5: 0.01466821 | D5: 2024Q2 | E5: 0.0086902988 | F5: 0.0059779115 | G5: 0.7253886 | H5: 192 | I5: Lebanon 0.27; Dover 0.18; Roanoke 0.14
A6: Fairbanks-College, AK | B6: -0.046902405 | C6: 0.0045421787 | D6: 2020Q3 | E6: -0.060368443 | F6: 0.064910622 | G6: 0.25388601 | H6: 192 | I6: Hattiesburg 0.31; Victoria 0.30; Florence 0.20

Sheet Ch8 reader decision
A1: ch8.largest: Source: the FHFA index anchored to the census, with Freddie Mac rates, model: the rent or buy breakeven, every metropolitan area with an anchored value, a census income and rent in 2024 (382 metros; 382 with enough history for the breakeven), as of 2026-10-23.
A3: Metro | B3: Median home | C3: Affordable price | D3: Can afford | E3: Affordable share | F3: Down payment years | G3: Breakeven | H3: Low | I3: High
A4: Boston-Cambridge-Newton, MA-NH | B4: 724836.19 | C4: 506109.3 | D4: no | E4: 0.34398758 | F4: 9.885388 | G4: 21 | H4: 2 | I4: 31
A5: Chicago-Naperville-Elgin, IL-IN | B5: 365616.78 | C5: 389896.38 | D5: yes | E5: 0.5312491 | F5: 6.5175817 | G5: 19.5 | H5: 2 | I5: 31
A6: San Francisco-Oakland-Fremont, CA | B6: 1161939.1 | C6: 582417.65 | D6: no | E6: 0.15999334 | F6: 12.37725 | G6: 18 | H6: 1 | I6: 31
A7: Minneapolis-St. Paul-Bloomington, MN-WI | B7: 391204.13 | C7: 420643.08 | D7: yes | E7: 0.5369152 | F7: 6.8548122 | G7: 18 | H7: 2 | I7: 31
A8: St. Louis, MO-IL | B8: 271171.95 | C8: 350846.61 | D8: yes | E8: 0.61236537 | F8: 5.5695849 | G8: 17 | H8: 2 | I8: 31
A9: New York-Newark-Jersey City, NY-NJ | B9: 709339.05 | C9: 428907.5 | D9: no | E9: 0.29975299 | F9: 10.589837 | G9: 16 | H9: 2 | I9: 31
A10: Denver-Aurora-Centennial, CO | B10: 625143.63 | C10: 464104.27 | D10: no | E10: 0.36045288 | F10: 8.6202928 | G10: 12 | H10: 2 | I10: 31
A11: Washington-Arlington-Alexandria, DC-VA-MD-WV | B11: 619214.49 | C11: 542272.54 | D11: no | E11: 0.44213782 | F11: 7.6357621 | G11: 11 | H11: 1 | I11: 31
A12: Detroit-Warren-Dearborn, MI | B12: 284812.2 | C12: 328183.91 | D12: yes | E12: 0.55917554 | F12: 6.2836386 | G12: 11 | H12: 2 | I12: 31
A13: Houston-Pasadena-The Woodlands, TX | B13: 313176.69 | C13: 349721.2 | D13: yes | E13: 0.55151325 | F13: 6.0025432 | G13: 8 | H13: 2 | I13: 24
A14: Philadelphia-Camden-Wilmington, PA-NJ-DE-MD | B14: 402522.79 | C14: 390240.01 | D14: no | E14: 0.48993207 | F14: 7.3473175 | G14: 8 | H14: 1 | I14: 31
A15: San Diego-Chula Vista-Carlsbad, CA | B15: 985574.54 | C15: 468769.11 | D15: no | E15: 0.1625117 | F15: 12.089824 | G15: 7 | H15: 1 | I15: 31
... A23: Tampa-St. Petersburg-Clearwater, FL | B23: 400906.52 | C23: 336224.95 | D23: no | E23: 0.42788373 | F23: 7.1630102 | G23: 3 | H23: 1 | I23: 31

Sheet Ch8 line interior test
A1: ch8.line_interior: Source: the FHFA index anchored to the census, with Freddie Mac rates, model: the payment at the quarterly rate, every metropolitan area with an anchored value, a census income and rent in 2024 (382 metros; 382 with enough history for the breakeven), as of 2026-10-23.
A3: Line | B3: Metros where the median household can afford the median home | C3: Share | D3: Note
A4: 0.25 | B4: 119 | C4: 0.31151832
A5: 0.28 | B5: 191 | C5: 0.5 | D5: degenerate
A6: 0.3 | B6: 221 | C6: 0.57853403 | D6: chosen
A7: 0.35 | B7: 288 | C7: 0.7539267

Sheet Ch8 down payment interior
A1: ch8.down_interior: Source: the FHFA index anchored to the census, with Freddie Mac rates, model: the rent or buy breakeven, every metropolitan area with an anchored value, a census income and rent in 2024 (382 metros; 382 with enough history for the breakeven), as of 2026-10-23.
A3: Down payment | B3: Median breakeven | C3: Median down payment years | D3: Note
A4: 0.05 | B4: 11 | C4: 3.1995665
A5: 0.1 | B5: 9.5 | C5: 6.3991331 | D5: chosen
A6: 0.2 | B6: 8 | C6: 12.798266

Sheet Ch8 saving rate interior
A1: ch8.saving_interior: Source: the FHFA index anchored to the census, with Freddie Mac rates, model: the payment at the quarterly rate, every metropolitan area with an anchored value, a census income and rent in 2024 (382 metros; 382 with enough history for the breakeven), as of 2026-10-23.
A3: Saving rate | B3: Median down payment years | C3: Note
A4: 0.05 | B4: 12.798266
A5: 0.1 | B5: 6.3991331 | C5: chosen
A6: 0.15 | B6: 4.2660887

Sheet Recovery by estimator
A1: recovery.by_estimator: Source: the simulated metros with known truth, the recovery study, every condition and seed, 20 seeds, as of 2026-10-22.
A3: Estimator | B3: Mean bias | C3: Mean RMSE | D3: Mean coverage | E3: Mean flag rate | F3: Worst bias under | G3: Lowest coverage | H3: Lowest coverage under
A4: anchored_level | B4: -0.0014297026 | C4: 0.013505374 | F4: weak_demand/narrow_supply/none_reverse/high_noise
A5: anchored_payment_share | B5: -0.00017034448 | C5: 0.0037742241 | D5: 0.43333333 | F5: weak_demand/narrow_supply/none_reverse/low_noise | G5: 0.35 | H5: weak_demand/narrow_supply/mild_reverse/high_noise
A6: borrower_ratio_shift | B6: -0.0010799729 | C6: 0.0057655 | D6: 0.75625 | F6: strong_demand/narrow_supply/strong_reverse/high_noise | G6: 0.55 | H6: weak_demand/wide_supply/mild_reverse/low_noise
A7: bracket_interpolation | B7: 0.0037037639 | C7: 0.0039023726 | F7: weak_demand/narrow_supply/strong_reverse/high_noise
A8: breakeven_horizon | B8: 4.4167631 | C8: 4.4415355 | E8: 0.69776235 | F8: weak_demand/narrow_supply/strong_reverse/low_noise
A9: burden_changepoint | B9: 0.0041666667 | C9: 0.0186339 | E9: 1 | F9: strong_demand/narrow_supply/strong_reverse/low_noise
A10: lock_in_did | B10: 0.001489173 | C10: 0.0055339918 | D10: 0.94166667 | E10: 0.85 | F10: weak_demand/narrow_supply/none_reverse/high_noise | G10: 0.85 | H10: weak_demand/narrow_supply/strong_reverse/high_noise
A11: lock_in_placebo | B11: -7.0222443e-05 | C11: 0.0086530805 | D11: 0.85 | F11: strong_demand/narrow_supply/none_reverse/high_noise | G11: 0.8 | H11: strong_demand/narrow_supply/mild_reverse/high_noise
A12: migration_effect | B12: -0.00023134288 | C12: 0.0026731171 | D12: 0.975 | E12: 0.18333333 | F12: strong_demand/wide_supply/strong_reverse/low_noise | G12: 0.95 | H12: strong_demand/narrow_supply/none_reverse/low_noise
A13: migration_naive | B13: -0.0035625457 | C13: 0.0042590045 | D13: 0.60833333 | F13: strong_demand/wide_supply/strong_reverse/low_noise | G13: 0.05 | H13: strong_demand/narrow_supply/strong_reverse/low_noise
A14: migration_placebo | B14: -0.0026879072 | C14: 0.0042742463 | D14: 0.81666667 | F14: strong_demand/wide_supply/strong_reverse/high_noise | G14: 0.15 | H14: strong_demand/narrow_supply/strong_reverse/high_noise
A15: ranking_adjusted | B15: -0.043670192 | C15: 0.047478487 | E15: 0.88961375 | F15: strong_demand/narrow_supply/strong_reverse/low_noise
A16: self_report_correction | B16: -0.0015104506 | C16: 0.003356649 | E16: 0.017321166 | F16: weak_demand/wide_supply/mild_reverse/low_noise
A17: severe_share | B17: -4.1633363e-18 | C17: 1.1459606e-16 | D17: 1 | F17: strong_demand/narrow_supply/none_reverse/low_noise | G17: 1 | H17: strong_demand/narrow_supply/mild_reverse/high_noise
A18: supply_controlled | B18: 0.0026476466 | C18: 0.0042824341 | D18: 0.84791667 | F18: strong_demand/narrow_supply/strong_reverse/high_noise | G18: 0.7 | H18: strong_demand/wide_supply/strong_reverse/high_noise
A19: supply_uncontrolled | B19: 0.0058485438 | C19: 0.0069914623 | D19: 0.70208333 | F19: strong_demand/narrow_supply/strong_reverse/high_noise | G19: 0.3 | H19: strong_demand/narrow_supply/strong_reverse/high_noise
A20: under_35_shift | B20: -0.00016474168 | C20: 0.0017753768 | D20: 0.85416667 | F20: strong_demand/wide_supply/mild_reverse/high_noise | G20: 0.6 | H20: strong_demand/wide_supply/mild_reverse/high_noise

Sheet Recovery by condition
A1: recovery.by_condition: Source: the simulated metros with known truth, the recovery study, every condition and seed, 20 seeds, as of 2026-10-22.
A3: Estimator | B3: Condition | C3: Seeds | D3: Bias | E3: RMSE | F3: Coverage | G3: Flag rate
A4: anchored_level | B4: strong_demand/narrow_supply/mild_reverse/high_noise | C4: 20 | D4: 0.00029185523 | E4: 0.01090325
A5: anchored_level | B5: strong_demand/narrow_supply/mild_reverse/low_noise | C5: 20 | D5: 0.0001438321 | E5: 0.010984314
A6: anchored_level | B6: strong_demand/narrow_supply/none_reverse/high_noise | C6: 20 | D6: 0.00040562307 | E6: 0.012476812
A7: anchored_level | B7: strong_demand/narrow_supply/none_reverse/low_noise | C7: 20 | D7: 0.00030295502 | E7: 0.012502104
A8: anchored_level | B8: strong_demand/narrow_supply/strong_reverse/high_noise | C8: 20 | D8: 5.5787262e-05 | E8: 0.0096516527
A9: anchored_level | B9: strong_demand/narrow_supply/strong_reverse/low_noise | C9: 20 | D9: -0.00010764688 | E9: 0.0095798544
A10: anchored_level | B10: strong_demand/wide_supply/mild_reverse/high_noise | C10: 20 | D10: 0.00038062072 | E10: 0.010935879
A11: anchored_level | B11: strong_demand/wide_supply/mild_reverse/low_noise | C11: 20 | D11: 0.00023214353 | E11: 0.011013125
A12: anchored_level | B12: strong_demand/wide_supply/none_reverse/high_noise | C12: 20 | D12: 0.00050766002 | E12: 0.012563669
A13: anchored_level | B13: strong_demand/wide_supply/none_reverse/low_noise | C13: 20 | D13: 0.00040127258 | E13: 0.012590342
A14: anchored_level | B14: strong_demand/wide_supply/strong_reverse/high_noise | C14: 20 | D14: 0.00013067196 | E14: 0.0096453088
A15: anchored_level | B15: strong_demand/wide_supply/strong_reverse/low_noise | C15: 20 | D15: -3.5643038e-05 | E15: 0.0095620946
... A27: anchored_level | B27: weak_demand/wide_supply/strong_reverse/low_noise | C27: 20 | D27: -0.0029766928 | E27: 0.016155253
A28: anchored_payment_share | B28: strong_demand/narrow_supply/mild_reverse/high_noise | C28: 20 | D28: 0.00030027256 | E28: 0.0029636435 | F28: 0.5
A29: anchored_payment_share | B29: strong_demand/narrow_supply/mild_reverse/low_noise | C29: 20 | D29: 0.00027749196 | E29: 0.0029895806 | F29: 0.45
A30: anchored_payment_share | B30: strong_demand/narrow_supply/none_reverse/high_noise | C30: 20 | D30: 0.00035354113 | E30: 0.0036264196 | F30: 0.5
A31: anchored_payment_share | B31: strong_demand/narrow_supply/none_reverse/low_noise | C31: 20 | D31: 0.0003540447 | E31: 0.0036332792 | F31: 0.5
A32: anchored_payment_share | B32: strong_demand/narrow_supply/strong_reverse/high_noise | C32: 20 | D32: 0.00016672406 | E32: 0.0025071821 | F32: 0.5
A33: anchored_payment_share | B33: strong_demand/narrow_supply/strong_reverse/low_noise | C33: 20 | D33: 0.000129383 | E33: 0.0025199412 | F33: 0.5
A34: anchored_payment_share | B34: strong_demand/wide_supply/mild_reverse/high_noise | C34: 20 | D34: 0.00032838543 | E34: 0.0029733872 | F34: 0.5
A35: anchored_payment_share | B35: strong_demand/wide_supply/mild_reverse/low_noise | C35: 20 | D35: 0.00030589515 | E35: 0.0029992507 | F35: 0.45
A36: anchored_payment_share | B36: strong_demand/wide_supply/none_reverse/high_noise | C36: 20 | D36: 0.00039233586 | E36: 0.0036485027 | F36: 0.5
A37: anchored_payment_share | B37: strong_demand/wide_supply/none_reverse/low_noise | C37: 20 | D37: 0.00039253872 | E37: 0.0036587375 | F37: 0.5
A38: anchored_payment_share | B38: strong_demand/wide_supply/strong_reverse/high_noise | C38: 20 | D38: 0.00018900045 | E38: 0.0025109849 | F38: 0.5
A39: anchored_payment_share | B39: strong_demand/wide_supply/strong_reverse/low_noise | C39: 20 | D39: 0.00015061769 | E39: 0.0025209306 | F39: 0.5
... A75: borrower_ratio_shift | B75: weak_demand/wide_supply/strong_reverse/low_noise | C75: 20 | D75: -0.00040753663 | E75: 0.0057948321 | F75: 0.7
A76: bracket_interpolation | B76: strong_demand/narrow_supply/mild_reverse/high_noise | C76: 20 | D76: 0.0036322475 | E76: 0.0039052963
A77: bracket_interpolation | B77: strong_demand/narrow_supply/mild_reverse/low_noise | C77: 20 | D77: 0.0034577996 | E77: 0.0037657857
A78: bracket_interpolation | B78: strong_demand/narrow_supply/none_reverse/high_noise | C78: 20 | D78: 0.0039407481 | E78: 0.0041771034
A79: bracket_interpolation | B79: strong_demand/narrow_supply/none_reverse/low_noise | C79: 20 | D79: 0.0037997208 | E79: 0.0040680413
A80: bracket_interpolation | B80: strong_demand/narrow_supply/strong_reverse/high_noise | C80: 20 | D80: 0.0027077847 | E80: 0.0029003628
A81: bracket_interpolation | B81: strong_demand/narrow_supply/strong_reverse/low_noise | C81: 20 | D81: 0.0025288211 | E81: 0.0026222547
A82: bracket_interpolation | B82: strong_demand/wide_supply/mild_reverse/high_noise | C82: 20 | D82: 0.0036399326 | E82: 0.0038938351
A83: bracket_interpolation | B83: strong_demand/wide_supply/mild_reverse/low_noise | C83: 20 | D83: 0.0034350173 | E83: 0.0037172522
A84: bracket_interpolation | B84: strong_demand/wide_supply/none_reverse/high_noise | C84: 20 | D84: 0.0038913962 | E84: 0.0041097521
A85: bracket_interpolation | B85: strong_demand/wide_supply/none_reverse/low_noise | C85: 20 | D85: 0.0037201887 | E85: 0.0039731928
A86: bracket_interpolation | B86: strong_demand/wide_supply/strong_reverse/high_noise | C86: 20 | D86: 0.0026821954 | E86: 0.0028629875
A87: bracket_interpolation | B87: strong_demand/wide_supply/strong_reverse/low_noise | C87: 20 | D87: 0.002527834 | E87: 0.0026239079
...

Sheet Metric definitions
A1: metrics.definitions: Source: several sources, every metro and year in the window, through the metric layer, as of 2026-10-23.
A3: Metric | B3: Over the grain | C3: Over the mart
A4: households | B4: sum(estimate) filter (where variable = 'B11001_001') | C4: sum(households)
A5: owner households | B5: sum(estimate) filter (where variable = 'B25003_002') | C5: sum(owner_households)
A6: renter households | B6: sum(estimate) filter (where variable = 'B25003_003') | C6: sum(renter_households)
A7: renters burdened | B7: sum(estimate) filter (where variable in ('B25070_007', 'B25070_008', 'B25070_009', 'B25070_010')) | C7: sum(renters_burdened)
A8: renters severe | B8: sum(estimate) filter (where variable = 'B25070_010') | C8: sum(renters_severe)
A9: renter burdened share | B9: sum(estimate) filter (where variable in ('B25070_007', 'B25070_008', 'B25070_009', 'B25070_010')) / (sum(estimate) filter (where variable = 'B25070_001') - coalesce(sum(estimate) filter (where variable = 'B25070_011'), 0)) | C9: sum(renters_burdened) / sum(renters_with_share)
A10: housing units | B10: sum(estimate) filter (where variable = 'B25001_001') | C10: sum(housing_units)
A11: permits | B11: sum(permits) | C11: sum(permits)
A12: population | B12: sum(population) | C12: sum(population)
A13: domestic migration | B13: sum(domestic_migration) | C13: sum(domestic_migration)
A14: purchase loans | B14: count(*) filter (where loan_purpose = 1) | C14: sum(purchase_loans)
... A24: price to income ratio of sums | B24: sum(value_anchored) / sum(median_income) | C24: sum(value_anchored) / sum(median_income)
